Workbook
Name NativeTimeline_Sale_Date: #N/A
Name NativeTimeline_Sale_Date1: #N/A

Sheet Model Overview
A1: INVENTORY RISK & REPLENISHMENT DECISION SUPPORT MODEL
A2: An Excel-based inventory model designed to identify inventory risks, prioritize products for replenishment, and provide order quantity recommendations
A3: Business Objective
A4: Develop an Excel-based inventory monitoring system that transforms sales and inventory data into actionable replenishment recommendations. The model helps identify stock shortages, assess inventory risk, prioritize SKUs requiring attention, and recommend replenishment quantities.
A8: Model Workflow
A9: Sales Data→ Inventory Analysis→ Stock Status→ Inventory Risk→ Order Priority→ Replenishment Recommnedation
A13: Key Inventory Metrics
A14: Metric | B14: Purpose
A15: Daily Demand | B15: Estimates typical daily product demand
A16: Safety Stock | B16: Provides inventory protection against uncertainty
A17: Reorder Point | B17: Indicates when replenishment should be triggered
A18: Days of Supply | B18: Estimates how long current inventory can support demand
A19: Safety Stock Gap | B19: Measures the shortage relative to required safety stock
A20: Stock Status | B20: Classifies inventory as Safe, Reorder, Critical, or Stockout
A21: Risk Level | B21: Evaluates the severity of the inventory situation
A22: Order Priority | B22: Converts inventory risk into purchasing priority
A23: Recommended Order Quantity | B23: Suggests replenishment quantity for purchasing review
A25: Model Assumptions
A26: Dataset is simulated for portfolio demonstration purposes.
A27: Average Daily Demand uses the most recent completed month's sales.
A28: Lead time is maintained by supplier/product category.
A29: Reorder Point = (Average Daily Demand × Lead Time) + Safety Stock.
A30: Inventory risk is determined using stock position, Days of Supply, lead time, and safety-stock gap.
A31: Recommended quantities are planning recommendations and require managerial review before purchase orders are issued.
A33: Automated Workflow
A34: Once new sales and inventory data are updated, the model automatically evaluates stock status, inventory risk, order priority, and replenishment recommendations to support inventory decisions.
A37: New Data Sales → Updated Demand Calculated → Stock on Hand Updated → Stock Status Automatically Updated → Inventory Risk Automatically Updated → Order Priority Automatically Updated → Replenishment Recommendations Automatically Updated

Sheet Products
A1: SKU | B1: Product Name | C1: Category | D1: Supplier | E1: Supplier ID | F1: Unit Cost (CAD) | G1: Selling Price (CAD)
A2: WEN-BUR-001 | B2: Classic Single Burger | C2: Burgers | D2: =_xlfn.XLOOKUP(Products[[#This Row],[Category]],'Supplier Mapping'!$C$2:$C$11,'Supplier Mapping'!$A$2:$A$11) -> Maple Prairie Foods | E2: =_xlfn.XLOOKUP(Products[[#This Row],[Supplier]],'Supplier Mapping'!$A$2:$A$11,'Supplier Mapping'!$B$2:$B$11) -> SUP01 | F2: 1.7 | G2: 5.99
A3: WEN-BUR-002 | B3: Classic Double Burger | C3: Burgers | D3: =_xlfn.XLOOKUP(Products[[#This Row],[Category]],'Supplier Mapping'!$C$2:$C$11,'Supplier Mapping'!$A$2:$A$11) -> Maple Prairie Foods | E3: =_xlfn.XLOOKUP(Products[[#This Row],[Supplier]],'Supplier Mapping'!$A$2:$A$11,'Supplier Mapping'!$B$2:$B$11) -> SUP01 | F3: 2.57 | G3: 7.99
A4: WEN-BUR-003 | B4: Classic Triple Burger | C4: Burgers | D4: =_xlfn.XLOOKUP(Products[[#This Row],[Category]],'Supplier Mapping'!$C$2:$C$11,'Supplier Mapping'!$A$2:$A$11) -> Maple Prairie Foods | E4: =_xlfn.XLOOKUP(Products[[#This Row],[Supplier]],'Supplier Mapping'!$A$2:$A$11,'Supplier Mapping'!$B$2:$B$11) -> SUP01 | F4: 3.6 | G4: 9.99
A5: WEN-BUR-004 | B5: Cheese Single Burger | C5: Burgers | D5: =_xlfn.XLOOKUP(Products[[#This Row],[Category]],'Supplier Mapping'!$C$2:$C$11,'Supplier Mapping'!$A$2:$A$11) -> Maple Prairie Foods | E5: =_xlfn.XLOOKUP(Products[[#This Row],[Supplier]],'Supplier Mapping'!$A$2:$A$11,'Supplier Mapping'!$B$2:$B$11) -> SUP01 | F5: 1.84 | G5: 5.99
A6: WEN-BUR-005 | B6: Cheese Double Burger | C6: Burgers | D6: =_xlfn.XLOOKUP(Products[[#This Row],[Category]],'Supplier Mapping'!$C$2:$C$11,'Supplier Mapping'!$A$2:$A$11) -> Maple Prairie Foods | E6: =_xlfn.XLOOKUP(Products[[#This Row],[Supplier]],'Supplier Mapping'!$A$2:$A$11,'Supplier Mapping'!$B$2:$B$11) -> SUP01 | F6: 2.83 | G6: 7.99
A7: WEN-BUR-006 | B7: Cheese Triple Burger | C7: Burgers | D7: =_xlfn.XLOOKUP(Products[[#This Row],[Category]],'Supplier Mapping'!$C$2:$C$11,'Supplier Mapping'!$A$2:$A$11) -> Maple Prairie Foods | E7: =_xlfn.XLOOKUP(Products[[#This Row],[Supplier]],'Supplier Mapping'!$A$2:$A$11,'Supplier Mapping'!$B$2:$B$11) -> SUP01 | F7: 3.7 | G7: 9.99
A8: WEN-BUR-007 | B8: Bacon Single Burger | C8: Burgers | D8: =_xlfn.XLOOKUP(Products[[#This Row],[Category]],'Supplier Mapping'!$C$2:$C$11,'Supplier Mapping'!$A$2:$A$11) -> Maple Prairie Foods | E8: =_xlfn.XLOOKUP(Products[[#This Row],[Supplier]],'Supplier Mapping'!$A$2:$A$11,'Supplier Mapping'!$B$2:$B$11) -> SUP01 | F8: 2.03 | G8: 6.99
A9: WEN-BUR-008 | B9: Bacon Double Burger | C9: Burgers | D9: =_xlfn.XLOOKUP(Products[[#This Row],[Category]],'Supplier Mapping'!$C$2:$C$11,'Supplier Mapping'!$A$2:$A$11) -> Maple Prairie Foods | E9: =_xlfn.XLOOKUP(Products[[#This Row],[Supplier]],'Supplier Mapping'!$A$2:$A$11,'Supplier Mapping'!$B$2:$B$11) -> SUP01 | F9: 3.02 | G9: 8.99
A10: WEN-BUR-009 | B10: Bacon Triple Burger | C10: Burgers | D10: =_xlfn.XLOOKUP(Products[[#This Row],[Category]],'Supplier Mapping'!$C$2:$C$11,'Supplier Mapping'!$A$2:$A$11) -> Maple Prairie Foods | E10: =_xlfn.XLOOKUP(Products[[#This Row],[Supplier]],'Supplier Mapping'!$A$2:$A$11,'Supplier Mapping'!$B$2:$B$11) -> SUP01 | F10: 3.79 | G10: 10.99
A11: WEN-BUR-010 | B11: Mushroom Swiss Single Burger | C11: Burgers | D11: =_xlfn.XLOOKUP(Products[[#This Row],[Category]],'Supplier Mapping'!$C$2:$C$11,'Supplier Mapping'!$A$2:$A$11) -> Maple Prairie Foods | E11: =_xlfn.XLOOKUP(Products[[#This Row],[Supplier]],'Supplier Mapping'!$A$2:$A$11,'Supplier Mapping'!$B$2:$B$11) -> SUP01 | F11: 2.09 | G11: 6.99
A12: WEN-BUR-011 | B12: Mushroom Swiss Double Burger | C12: Burgers | D12: =_xlfn.XLOOKUP(Products[[#This Row],[Category]],'Supplier Mapping'!$C$2:$C$11,'Supplier Mapping'!$A$2:$A$11) -> Maple Prairie Foods | E12: =_xlfn.XLOOKUP(Products[[#This Row],[Supplier]],'Supplier Mapping'!$A$2:$A$11,'Supplier Mapping'!$B$2:$B$11) -> SUP01 | F12: 2.92 | G12: 8.99
A13: WEN-BUR-012 | B13: Jalapeño Cheddar Single Burger | C13: Burgers | D13: =_xlfn.XLOOKUP(Products[[#This Row],[Category]],'Supplier Mapping'!$C$2:$C$11,'Supplier Mapping'!$A$2:$A$11) -> Maple Prairie Foods | E13: =_xlfn.XLOOKUP(Products[[#This Row],[Supplier]],'Supplier Mapping'!$A$2:$A$11,'Supplier Mapping'!$B$2:$B$11) -> SUP01 | F13: 1.93 | G13: 6.49
... A201: WEN-COM-010 | B201: Southwest Chicken Salad Combo | C201: Combo Meals | D201: =_xlfn.XLOOKUP(Products[[#This Row],[Category]],'Supplier Mapping'!$C$2:$C$11,'Supplier Mapping'!$A$2:$A$11) -> Canada QuickServe Distribution | E201: =_xlfn.XLOOKUP(Products[[#This Row],[Supplier]],'Supplier Mapping'!$A$2:$A$11,'Supplier Mapping'!$B$2:$B$11) -> SUP07 | F201: 4.66 | G201: 12.99

Sheet Supplier Mapping
A1: Suppliers | B1: Supplier ID | C1: Primary Category
A2: Maple Prairie Foods | B2: SUP01 | C2: Burgers
A3: Maple Prairie Foods | B3: SUP01 | C3: Chicken
A4: MorningStar Foodservice | B4: SUP02 | C4: Breakfast
A5: NorthStar Frozen Foods | B5: SUP03 | C5: Sides
A6: Fraser Fresh Produce | B6: SUP04 | C6: Salads
A7: Pacific Beverage Partners | B7: SUP05 | C7: Beverages
A8: SweetPeak Desserts | B8: SUP06 | C8: Desserts
A9: Canada QuickServe Distribution | B9: SUP07 | C9: Kids Meals
A10: Canada QuickServe Distribution | B10: SUP07 | C10: Combo Meals
A11: TrueNorth Sauces & Seasonings | B11: SUP08 | C11: Sauces & Add-ons

Sheet Sales
A1: Sale ID | B1: Sale Date | C1: SKU | D1: Product Name | E1: Category | F1: Store Location | G1: Sales Channel | H1: Quantity Sold | I1: Unit Selling Price (CAD) | J1: Sales Revenue (CAD)
A2: SAL-00001 | B2: 46023 | C2: WEN-COM-006 | D2: Crispy Chicken Combo | E2: =_xlfn.XLOOKUP(Sales[[#This Row],[Product Name]],Products[Product Name],Products[Category]) -> Combo Meals | F2: Kamloops - Downtown | G2: Delivery | H2: 61 | I2: =_xlfn.XLOOKUP(Sales[[#This Row],[Product Name]],Products[Product Name],Products[Selling Price (CAD)]) -> 9.99 | J2: =PRODUCT(Sales[[#This Row],[Quantity Sold]],Sales[[#This Row],[Unit Selling Price (CAD)]]) -> 609.39
A3: SAL-00002 | B3: 46023 | C3: WEN-KID-007 | D3: Kids Breakfast Sandwich Meal | E3: =_xlfn.XLOOKUP(Sales[[#This Row],[Product Name]],Products[Product Name],Products[Category]) -> Kids Meals | F3: Kamloops - Valleyview | G3: Delivery | H3: 42 | I3: =_xlfn.XLOOKUP(Sales[[#This Row],[Product Name]],Products[Product Name],Products[Selling Price (CAD)]) -> 5.99 | J3: =PRODUCT(Sales[[#This Row],[Quantity Sold]],Sales[[#This Row],[Unit Selling Price (CAD)]]) -> 251.58
A4: SAL-00003 | B4: 46023 | C4: WEN-CHK-002 | D4: Spicy Chicken Sandwich | E4: =_xlfn.XLOOKUP(Sales[[#This Row],[Product Name]],Products[Product Name],Products[Category]) -> Chicken | F4: Kamloops - Aberdeen | G4: Drive-Thru | H4: 62 | I4: =_xlfn.XLOOKUP(Sales[[#This Row],[Product Name]],Products[Product Name],Products[Selling Price (CAD)]) -> 6.99 | J4: =PRODUCT(Sales[[#This Row],[Quantity Sold]],Sales[[#This Row],[Unit Selling Price (CAD)]]) -> 433.38
A5: SAL-00004 | B5: 46023 | C5: WEN-SID-020 | D5: Loaded Fries | E5: =_xlfn.XLOOKUP(Sales[[#This Row],[Product Name]],Products[Product Name],Products[Category]) -> Sides | F5: Kamloops - Downtown | G5: Takeout | H5: 62 | I5: =_xlfn.XLOOKUP(Sales[[#This Row],[Product Name]],Products[Product Name],Products[Selling Price (CAD)]) -> 5.99 | J5: =PRODUCT(Sales[[#This Row],[Quantity Sold]],Sales[[#This Row],[Unit Selling Price (CAD)]]) -> 371.38
A6: SAL-00005 | B6: 46023 | C6: WEN-BEV-025 | D6: Hot Coffee - Small | E6: =_xlfn.XLOOKUP(Sales[[#This Row],[Product Name]],Products[Product Name],Products[Category]) -> Beverages | F6: Kamloops - Downtown | G6: Dine-In | H6: 78 | I6: =_xlfn.XLOOKUP(Sales[[#This Row],[Product Name]],Products[Product Name],Products[Selling Price (CAD)]) -> 1.99 | J6: =PRODUCT(Sales[[#This Row],[Quantity Sold]],Sales[[#This Row],[Unit Selling Price (CAD)]]) -> 155.22
A7: SAL-00006 | B7: 46023 | C7: WEN-BEV-027 | D7: Hot Coffee - Large | E7: =_xlfn.XLOOKUP(Sales[[#This Row],[Product Name]],Products[Product Name],Products[Category]) -> Beverages | F7: Kamloops - Valleyview | G7: Drive-Thru | H7: 78 | I7: =_xlfn.XLOOKUP(Sales[[#This Row],[Product Name]],Products[Product Name],Products[Selling Price (CAD)]) -> 2.99 | J7: =PRODUCT(Sales[[#This Row],[Quantity Sold]],Sales[[#This Row],[Unit Selling Price (CAD)]]) -> 233.22
A8: SAL-00007 | B8: 46023 | C8: WEN-BRK-016 | D8: Breakfast Potatoes - Large | E8: =_xlfn.XLOOKUP(Sales[[#This Row],[Product Name]],Products[Product Name],Products[Category]) -> Breakfast | F8: Kamloops - Downtown | G8: Dine-In | H8: 34 | I8: =_xlfn.XLOOKUP(Sales[[#This Row],[Product Name]],Products[Product Name],Products[Selling Price (CAD)]) -> 3.99 | J8: =PRODUCT(Sales[[#This Row],[Quantity Sold]],Sales[[#This Row],[Unit Selling Price (CAD)]]) -> 135.66
A9: SAL-00008 | B9: 46024 | C9: WEN-SAU-004 | D9: BBQ Sauce Cup | E9: =_xlfn.XLOOKUP(Sales[[#This Row],[Product Name]],Products[Product Name],Products[Category]) -> Sauces & Add-ons | F9: Kamloops - Aberdeen | G9: Drive-Thru | H9: 54 | I9: =_xlfn.XLOOKUP(Sales[[#This Row],[Product Name]],Products[Product Name],Products[Selling Price (CAD)]) -> 0.5 | J9: =PRODUCT(Sales[[#This Row],[Quantity Sold]],Sales[[#This Row],[Unit Selling Price (CAD)]]) -> 27
A10: SAL-00009 | B10: 46024 | C10: WEN-DES-018 | D10: Chocolate Shake - Small | E10: =_xlfn.XLOOKUP(Sales[[#This Row],[Product Name]],Products[Product Name],Products[Category]) -> Desserts | F10: Kamloops - Downtown | G10: Drive-Thru | H10: 36 | I10: =_xlfn.XLOOKUP(Sales[[#This Row],[Product Name]],Products[Product Name],Products[Selling Price (CAD)]) -> 4.99 | J10: =PRODUCT(Sales[[#This Row],[Quantity Sold]],Sales[[#This Row],[Unit Selling Price (CAD)]]) -> 179.64
A11: SAL-00010 | B11: 46024 | C11: WEN-BUR-003 | D11: Classic Triple Burger | E11: =_xlfn.XLOOKUP(Sales[[#This Row],[Product Name]],Products[Product Name],Products[Category]) -> Burgers | F11: Kamloops - Downtown | G11: Takeout | H11: 70 | I11: =_xlfn.XLOOKUP(Sales[[#This Row],[Product Name]],Products[Product Name],Products[Selling Price (CAD)]) -> 9.99 | J11: =PRODUCT(Sales[[#This Row],[Quantity Sold]],Sales[[#This Row],[Unit Selling Price (CAD)]]) -> 699.3
A12: SAL-00011 | B12: 46024 | C12: WEN-BEV-004 | D12: Diet Cola - Small | E12: =_xlfn.XLOOKUP(Sales[[#This Row],[Product Name]],Products[Product Name],Products[Category]) -> Beverages | F12: Kamloops - Aberdeen | G12: Drive-Thru | H12: 63 | I12: =_xlfn.XLOOKUP(Sales[[#This Row],[Product Name]],Products[Product Name],Products[Selling Price (CAD)]) -> 1.99 | J12: =PRODUCT(Sales[[#This Row],[Quantity Sold]],Sales[[#This Row],[Unit Selling Price (CAD)]]) -> 125.37
A13: SAL-00012 | B13: 46024 | C13: WEN-DES-020 | D13: Caramel Shake - Large | E13: =_xlfn.XLOOKUP(Sales[[#This Row],[Product Name]],Products[Product Name],Products[Category]) -> Desserts | F13: Kamloops - Aberdeen | G13: Delivery | H13: 57 | I13: =_xlfn.XLOOKUP(Sales[[#This Row],[Product Name]],Products[Product Name],Products[Selling Price (CAD)]) -> 5.99 | J13: =PRODUCT(Sales[[#This Row],[Quantity Sold]],Sales[[#This Row],[Unit Selling Price (CAD)]]) -> 341.43
... A1801: SAL-01800 | B1801: 46265 | C1801: WEN-BEV-001 | D1801: Cola - Small | E1801: =_xlfn.XLOOKUP(Sales[[#This Row],[Product Name]],Products[Product Name],Products[Category]) -> Beverages | F1801: Kamloops - Valleyview | G1801: Delivery | H1801: 46 | I1801: =_xlfn.XLOOKUP(Sales[[#This Row],[Product Name]],Products[Product Name],Products[Selling Price (CAD)]) -> 1.99 | J1801: =PRODUCT(Sales[[#This Row],[Quantity Sold]],Sales[[#This Row],[Unit Selling Price (CAD)]]) -> 91.54

Sheet Inventory for Aug-31
A1: SKU | B1: Stock on Hand Aug-01 | C1: Stock on Hand Aug-31 | D1: Daily Demand | E1: Lead Time (Days) | F1: Safety Stock | G1: Reorder Point | H1: Stock Status
A2: WEN-BUR-001 | B2: 146 | C2: =Inventory[[#This Row],[Stock on Hand Aug-01]]-SUMIF(Sales!$C$1571:$C$1801,Inventory[[#This Row],[SKU]],Sales!$H$1571:$H$1801) -> 55 | D2: =SUMIF(Sales!$C$1571:$C$1801,'Inventory for Aug-31'!A2,Sales!$H$1571:$H$1801)/31 -> 2.9354839 | E2: 4 | F2: 52 | G2: =Inventory[[#This Row],[Daily Demand ]]*Inventory[[#This Row],[Lead Time (Days)]]+Inventory[[#This Row],[Safety Stock]] -> 63.741935 | H2: {=_xlfn.IFS(Inventory[[#This Row],[Stock on Hand Aug-31]]=0,"Stockout",Inventory[[#This Row],[Stock on Hand Aug-31]]<Inventory[[#This Row],[Safety Stock]],"Critical",Inventory[[#This Row],[Stock on Hand Aug-31]]<=Inventory[[#This Row],[Reorder Point ]],"Reorder",Inventory[[#This Row],[Stock on Hand Aug-31]]>Inventory[[#This Row],[Reorder Point ]],"Safe")} -> Reorder
A3: WEN-BUR-002 | B3: 173 | C3: =Inventory[[#This Row],[Stock on Hand Aug-01]]-SUMIF(Sales!$C$1571:$C$1801,Inventory[[#This Row],[SKU]],Sales!$H$1571:$H$1801) -> 61 | D3: =SUMIF(Sales!$C$1571:$C$1801,'Inventory for Aug-31'!A3,Sales!$H$1571:$H$1801)/31 -> 3.6129032 | E3: 4 | F3: 36 | G3: =Inventory[[#This Row],[Daily Demand ]]*Inventory[[#This Row],[Lead Time (Days)]]+Inventory[[#This Row],[Safety Stock]] -> 50.451613 | H3: {=_xlfn.IFS(Inventory[[#This Row],[Stock on Hand Aug-31]]=0,"Stockout",Inventory[[#This Row],[Stock on Hand Aug-31]]<Inventory[[#This Row],[Safety Stock]],"Critical",Inventory[[#This Row],[Stock on Hand Aug-31]]<=Inventory[[#This Row],[Reorder Point ]],"Reorder",Inventory[[#This Row],[Stock on Hand Aug-31]]>Inventory[[#This Row],[Reorder Point ]],"Safe")} -> Safe
A4: WEN-BUR-003 | B4: 118 | C4: =Inventory[[#This Row],[Stock on Hand Aug-01]]-SUMIF(Sales!$C$1571:$C$1801,Inventory[[#This Row],[SKU]],Sales!$H$1571:$H$1801) -> 73 | D4: =SUMIF(Sales!$C$1571:$C$1801,'Inventory for Aug-31'!A4,Sales!$H$1571:$H$1801)/31 -> 1.4516129 | E4: 4 | F4: 69 | G4: =Inventory[[#This Row],[Daily Demand ]]*Inventory[[#This Row],[Lead Time (Days)]]+Inventory[[#This Row],[Safety Stock]] -> 74.806452 | H4: {=_xlfn.IFS(Inventory[[#This Row],[Stock on Hand Aug-31]]=0,"Stockout",Inventory[[#This Row],[Stock on Hand Aug-31]]<Inventory[[#This Row],[Safety Stock]],"Critical",Inventory[[#This Row],[Stock on Hand Aug-31]]<=Inventory[[#This Row],[Reorder Point ]],"Reorder",Inventory[[#This Row],[Stock on Hand Aug-31]]>Inventory[[#This Row],[Reorder Point ]],"Safe")} -> Reorder
A5: WEN-BUR-004 | B5: 149 | C5: =Inventory[[#This Row],[Stock on Hand Aug-01]]-SUMIF(Sales!$C$1571:$C$1801,Inventory[[#This Row],[SKU]],Sales!$H$1571:$H$1801) -> 59 | D5: =SUMIF(Sales!$C$1571:$C$1801,'Inventory for Aug-31'!A5,Sales!$H$1571:$H$1801)/31 -> 2.9032258 | E5: 4 | F5: 74 | G5: =Inventory[[#This Row],[Daily Demand ]]*Inventory[[#This Row],[Lead Time (Days)]]+Inventory[[#This Row],[Safety Stock]] -> 85.612903 | H5: {=_xlfn.IFS(Inventory[[#This Row],[Stock on Hand Aug-31]]=0,"Stockout",Inventory[[#This Row],[Stock on Hand Aug-31]]<Inventory[[#This Row],[Safety Stock]],"Critical",Inventory[[#This Row],[Stock on Hand Aug-31]]<=Inventory[[#This Row],[Reorder Point ]],"Reorder",Inventory[[#This Row],[Stock on Hand Aug-31]]>Inventory[[#This Row],[Reorder Point ]],"Safe")} -> Critical
A6: WEN-BUR-005 | B6: 130 | C6: =Inventory[[#This Row],[Stock on Hand Aug-01]]-SUMIF(Sales!$C$1571:$C$1801,Inventory[[#This Row],[SKU]],Sales!$H$1571:$H$1801) -> 69 | D6: =SUMIF(Sales!$C$1571:$C$1801,'Inventory for Aug-31'!A6,Sales!$H$1571:$H$1801)/31 -> 1.9677419 | E6: 4 | F6: 65 | G6: =Inventory[[#This Row],[Daily Demand ]]*Inventory[[#This Row],[Lead Time (Days)]]+Inventory[[#This Row],[Safety Stock]] -> 72.870968 | H6: {=_xlfn.IFS(Inventory[[#This Row],[Stock on Hand Aug-31]]=0,"Stockout",Inventory[[#This Row],[Stock on Hand Aug-31]]<Inventory[[#This Row],[Safety Stock]],"Critical",Inventory[[#This Row],[Stock on Hand Aug-31]]<=Inventory[[#This Row],[Reorder Point ]],"Reorder",Inventory[[#This Row],[Stock on Hand Aug-31]]>Inventory[[#This Row],[Reorder Point ]],"Safe")} -> Reorder
A7: WEN-BUR-006 | B7: 144 | C7: =Inventory[[#This Row],[Stock on Hand Aug-01]]-SUMIF(Sales!$C$1571:$C$1801,Inventory[[#This Row],[SKU]],Sales!$H$1571:$H$1801) -> 82 | D7: =SUMIF(Sales!$C$1571:$C$1801,'Inventory for Aug-31'!A7,Sales!$H$1571:$H$1801)/31 -> 2 | E7: 4 | F7: 64 | G7: =Inventory[[#This Row],[Daily Demand ]]*Inventory[[#This Row],[Lead Time (Days)]]+Inventory[[#This Row],[Safety Stock]] -> 72 | H7: {=_xlfn.IFS(Inventory[[#This Row],[Stock on Hand Aug-31]]=0,"Stockout",Inventory[[#This Row],[Stock on Hand Aug-31]]<Inventory[[#This Row],[Safety Stock]],"Critical",Inventory[[#This Row],[Stock on Hand Aug-31]]<=Inventory[[#This Row],[Reorder Point ]],"Reorder",Inventory[[#This Row],[Stock on Hand Aug-31]]>Inventory[[#This Row],[Reorder Point ]],"Safe")} -> Safe
A8: WEN-BUR-007 | B8: 18 | C8: =Inventory[[#This Row],[Stock on Hand Aug-01]]-SUMIF(Sales!$C$1571:$C$1801,Inventory[[#This Row],[SKU]],Sales!$H$1571:$H$1801) -> 18 | D8: =SUMIF(Sales!$C$1571:$C$1801,'Inventory for Aug-31'!A8,Sales!$H$1571:$H$1801)/31 -> 0 | E8: 4 | F8: 47 | G8: =Inventory[[#This Row],[Daily Demand ]]*Inventory[[#This Row],[Lead Time (Days)]]+Inventory[[#This Row],[Safety Stock]] -> 47 | H8: {=_xlfn.IFS(Inventory[[#This Row],[Stock on Hand Aug-31]]=0,"Stockout",Inventory[[#This Row],[Stock on Hand Aug-31]]<Inventory[[#This Row],[Safety Stock]],"Critical",Inventory[[#This Row],[Stock on Hand Aug-31]]<=Inventory[[#This Row],[Reorder Point ]],"Reorder",Inventory[[#This Row],[Stock on Hand Aug-31]]>Inventory[[#This Row],[Reorder Point ]],"Safe")} -> Critical
A9: WEN-BUR-008 | B9: 174 | C9: =Inventory[[#This Row],[Stock on Hand Aug-01]]-SUMIF(Sales!$C$1571:$C$1801,Inventory[[#This Row],[SKU]],Sales!$H$1571:$H$1801) -> 0 | D9: =SUMIF(Sales!$C$1571:$C$1801,'Inventory for Aug-31'!A9,Sales!$H$1571:$H$1801)/31 -> 5.6129032 | E9: 4 | F9: 68 | G9: =Inventory[[#This Row],[Daily Demand ]]*Inventory[[#This Row],[Lead Time (Days)]]+Inventory[[#This Row],[Safety Stock]] -> 90.451613 | H9: {=_xlfn.IFS(Inventory[[#This Row],[Stock on Hand Aug-31]]=0,"Stockout",Inventory[[#This Row],[Stock on Hand Aug-31]]<Inventory[[#This Row],[Safety Stock]],"Critical",Inventory[[#This Row],[Stock on Hand Aug-31]]<=Inventory[[#This Row],[Reorder Point ]],"Reorder",Inventory[[#This Row],[Stock on Hand Aug-31]]>Inventory[[#This Row],[Reorder Point ]],"Safe")} -> Stockout
A10: WEN-BUR-009 | B10: 197 | C10: =Inventory[[#This Row],[Stock on Hand Aug-01]]-SUMIF(Sales!$C$1571:$C$1801,Inventory[[#This Row],[SKU]],Sales!$H$1571:$H$1801) -> 50 | D10: =SUMIF(Sales!$C$1571:$C$1801,'Inventory for Aug-31'!A10,Sales!$H$1571:$H$1801)/31 -> 4.7419355 | E10: 4 | F10: 37 | G10: =Inventory[[#This Row],[Daily Demand ]]*Inventory[[#This Row],[Lead Time (Days)]]+Inventory[[#This Row],[Safety Stock]] -> 55.967742 | H10: {=_xlfn.IFS(Inventory[[#This Row],[Stock on Hand Aug-31]]=0,"Stockout",Inventory[[#This Row],[Stock on Hand Aug-31]]<Inventory[[#This Row],[Safety Stock]],"Critical",Inventory[[#This Row],[Stock on Hand Aug-31]]<=Inventory[[#This Row],[Reorder Point ]],"Reorder",Inventory[[#This Row],[Stock on Hand Aug-31]]>Inventory[[#This Row],[Reorder Point ]],"Safe")} -> Reorder
A11: WEN-BUR-010 | B11: 111 | C11: =Inventory[[#This Row],[Stock on Hand Aug-01]]-SUMIF(Sales!$C$1571:$C$1801,Inventory[[#This Row],[SKU]],Sales!$H$1571:$H$1801) -> 72 | D11: =SUMIF(Sales!$C$1571:$C$1801,'Inventory for Aug-31'!A11,Sales!$H$1571:$H$1801)/31 -> 1.2580645 | E11: 4 | F11: 56 | G11: =Inventory[[#This Row],[Daily Demand ]]*Inventory[[#This Row],[Lead Time (Days)]]+Inventory[[#This Row],[Safety Stock]] -> 61.032258 | H11: {=_xlfn.IFS(Inventory[[#This Row],[Stock on Hand Aug-31]]=0,"Stockout",Inventory[[#This Row],[Stock on Hand Aug-31]]<Inventory[[#This Row],[Safety Stock]],"Critical",Inventory[[#This Row],[Stock on Hand Aug-31]]<=Inventory[[#This Row],[Reorder Point ]],"Reorder",Inventory[[#This Row],[Stock on Hand Aug-31]]>Inventory[[#This Row],[Reorder Point ]],"Safe")} -> Safe
A12: WEN-BUR-011 | B12: 187 | C12: =Inventory[[#This Row],[Stock on Hand Aug-01]]-SUMIF(Sales!$C$1571:$C$1801,Inventory[[#This Row],[SKU]],Sales!$H$1571:$H$1801) -> 82 | D12: =SUMIF(Sales!$C$1571:$C$1801,'Inventory for Aug-31'!A12,Sales!$H$1571:$H$1801)/31 -> 3.3870968 | E12: 4 | F12: 75 | G12: =Inventory[[#This Row],[Daily Demand ]]*Inventory[[#This Row],[Lead Time (Days)]]+Inventory[[#This Row],[Safety Stock]] -> 88.548387 | H12: {=_xlfn.IFS(Inventory[[#This Row],[Stock on Hand Aug-31]]=0,"Stockout",Inventory[[#This Row],[Stock on Hand Aug-31]]<Inventory[[#This Row],[Safety Stock]],"Critical",Inventory[[#This Row],[Stock on Hand Aug-31]]<=Inventory[[#This Row],[Reorder Point ]],"Reorder",Inventory[[#This Row],[Stock on Hand Aug-31]]>Inventory[[#This Row],[Reorder Point ]],"Safe")} -> Reorder
A13: WEN-BUR-012 | B13: 71 | C13: =Inventory[[#This Row],[Stock on Hand Aug-01]]-SUMIF(Sales!$C$1571:$C$1801,Inventory[[#This Row],[SKU]],Sales!$H$1571:$H$1801) -> 19 | D13: =SUMIF(Sales!$C$1571:$C$1801,'Inventory for Aug-31'!A13,Sales!$H$1571:$H$1801)/31 -> 1.6774194 | E13: 4 | F13: 49 | G13: =Inventory[[#This Row],[Daily Demand ]]*Inventory[[#This Row],[Lead Time (Days)]]+Inventory[[#This Row],[Safety Stock]] -> 55.709677 | H13: {=_xlfn.IFS(Inventory[[#This Row],[Stock on Hand Aug-31]]=0,"Stockout",Inventory[[#This Row],[Stock on Hand Aug-31]]<Inventory[[#This Row],[Safety Stock]],"Critical",Inventory[[#This Row],[Stock on Hand Aug-31]]<=Inventory[[#This Row],[Reorder Point ]],"Reorder",Inventory[[#This Row],[Stock on Hand Aug-31]]>Inventory[[#This Row],[Reorder Point ]],"Safe")} -> Critical
... A201: WEN-COM-010 | B201: 138 | C201: =Inventory[[#This Row],[Stock on Hand Aug-01]]-SUMIF(Sales!$C$1571:$C$1801,Inventory[[#This Row],[SKU]],Sales!$H$1571:$H$1801) -> 49 | D201: =SUMIF(Sales!$C$1571:$C$1801,'Inventory for Aug-31'!A201,Sales!$H$1571:$H$1801)/31 -> 2.8709677 | E201: 7 | F201: 52 | G201: =Inventory[[#This Row],[Daily Demand ]]*Inventory[[#This Row],[Lead Time (Days)]]+Inventory[[#This Row],[Safety Stock]] -> 72.096774 | H201: {=_xlfn.IFS(Inventory[[#This Row],[Stock on Hand Aug-31]]=0,"Stockout",Inventory[[#This Row],[Stock on Hand Aug-31]]<Inventory[[#This Row],[Safety Stock]],"Critical",Inventory[[#This Row],[Stock on Hand Aug-31]]<=Inventory[[#This Row],[Reorder Point ]],"Reorder",Inventory[[#This Row],[Stock on Hand Aug-31]]>Inventory[[#This Row],[Reorder Point ]],"Safe")} -> Critical

Sheet Inventory Risk
A1: SKU | B1: Stock on Hand Aug-31 | C1: Daily Demand | D1: Lead Time (Days) | E1: Days of Supply | F1: Safety Stock Gap | G1: Safety Stock | H1: Reorder Point | I1: Stock Status | J1: Risk Level | K1: Order Priority
A2: {=_xlfn._xlws.FILTER(Inventory[SKU],Inventory[[Stock Status ]]<>"Safe","")} -> WEN-BUR-001 | B2: {=_xlfn.XLOOKUP(_xlfn.ANCHORARRAY(A2),Inventory[SKU],Inventory[Stock on Hand Aug-31])} -> 55 | C2: {=_xlfn.XLOOKUP(_xlfn.ANCHORARRAY(A2),Inventory[SKU],Inventory[[Daily Demand ]])} -> 2.9354839 | D2: {=_xlfn.XLOOKUP(_xlfn.ANCHORARRAY(A2),Inventory[SKU],Inventory[Lead Time (Days)])} -> 4 | E2: {=IFERROR(_xlfn.ANCHORARRAY(B2)/_xlfn.ANCHORARRAY(C2),"No Demand" )} -> 18.736264 | F2: {=IF(_xlfn.ANCHORARRAY(I2)="Critical",(_xlfn.ANCHORARRAY(G2)-_xlfn.ANCHORARRAY(B2))/_xlfn.ANCHORARRAY(G2),"")} | G2: {=_xlfn.XLOOKUP(_xlfn.ANCHORARRAY(A2),Inventory[SKU],Inventory[Safety Stock])} -> 52 | H2: {=_xlfn.XLOOKUP(_xlfn.ANCHORARRAY(A2),Inventory[SKU],Inventory[[Reorder Point ]])} -> 63.741935 | I2: {=_xlfn.XLOOKUP(_xlfn.ANCHORARRAY(A2),Inventory[SKU],Inventory[[Stock Status ]])} -> Reorder | J2: {=_xlfn.IFS(_xlfn.ANCHORARRAY(B2)=0,"Very High",(_xlfn.ANCHORARRAY(D2)>=_xlfn.ANCHORARRAY(E2))*(_xlfn.ANCHORARRAY(I2)="Critical"),"High",(_xlfn.ANCHORARRAY(D2)<_xlfn.ANCHORARRAY(E2))*(_xlfn.ANCHORARRAY(I2)="Critical")*(_xlfn.ANCHORARRAY(F2)>30%),"High",(_xlfn.ANCHORARRAY(D2)<_xlfn.ANCHORARRAY(E2))*(_xlfn.ANCHORARRAY(I2)="Critical")*(_xlfn.ANCHORARRAY(F2)<=30%),"Medium",(_xlfn.ANCHORARRAY(D2)<=_xlfn.ANCHORARRAY(E2))*(_xlfn.ANCHORARRAY(E2)<=_xlfn.ANCHORARRAY(D2)+7)*(_xlfn.ANCHORARRAY(I2)="Reorder"),"Medium",(_xlfn.ANCHORARRAY(E2)>_xlfn.ANCHORARRAY(D2)+7)*(_xlfn.ANCHORARRAY(I2)="Reorder"),"Low",(_xlfn.ANCHORARRAY(E2)<=_xlfn.ANCHORARRAY(D2))*(_xlfn.ANCHORARRAY(I2)="Reorder"),"High")} -> Low | K2: {=_xlfn.IFS((_xlfn.ANCHORARRAY(I2)="Critical")*(_xlfn.ANCHORARRAY(J2)="High"),"High Priority",(_xlfn.ANCHORARRAY(I2)="Critical")*(_xlfn.ANCHORARRAY(J2)="Medium"),"Priority",_xlfn.ANCHORARRAY(I2)="Stockout","Urgent",(_xlfn.ANCHORARRAY(I2)="Reorder")*(_xlfn.ANCHORARRAY(J2)="Medium"),"Need Plan to Reorder",(_xlfn.ANCHORARRAY(I2)="Reorder")*(_xlfn.ANCHORARRAY(J2)="Low"),"Order Later",(_xlfn.ANCHORARRAY(I2)="Reorder")*(_xlfn.ANCHORARRAY(J2)="High"),"High Priority")} -> Order Later
A3: WEN-BUR-003 | B3: 73 | C3: 1.4516129 | D3: 4 | E3: 50.288889 | G3: 69 | H3: 74.806452 | I3: Reorder | J3: Low | K3: Order Later
A4: WEN-BUR-004 | B4: 59 | C4: 2.9032258 | D4: 4 | E4: 20.322222 | F4: 0.2027027 | G4: 74 | H4: 85.612903 | I4: Critical | J4: Medium | K4: Priority
A5: WEN-BUR-005 | B5: 69 | C5: 1.9677419 | D5: 4 | E5: 35.065574 | G5: 65 | H5: 72.870968 | I5: Reorder | J5: Low | K5: Order Later
A6: WEN-BUR-007 | B6: 18 | C6: 0 | D6: 4 | E6: No Demand | F6: 0.61702128 | G6: 47 | H6: 47 | I6: Critical | J6: High | K6: High Priority
A7: WEN-BUR-008 | B7: 0 | C7: 5.6129032 | D7: 4 | E7: 0 | G7: 68 | H7: 90.451613 | I7: Stockout | J7: Very High | K7: Urgent
A8: WEN-BUR-009 | B8: 50 | C8: 4.7419355 | D8: 4 | E8: 10.544218 | G8: 37 | H8: 55.967742 | I8: Reorder | J8: Medium | K8: Need Plan to Reorder
A9: WEN-BUR-011 | B9: 82 | C9: 3.3870968 | D9: 4 | E9: 24.209524 | G9: 75 | H9: 88.548387 | I9: Reorder | J9: Low | K9: Order Later
A10: WEN-BUR-012 | B10: 19 | C10: 1.6774194 | D10: 4 | E10: 11.326923 | F10: 0.6122449 | G10: 49 | H10: 55.709677 | I10: Critical | J10: High | K10: High Priority
A11: WEN-BUR-013 | B11: 52 | C11: 1.483871 | D11: 4 | E11: 35.043478 | G11: 50 | H11: 55.935484 | I11: Reorder | J11: Low | K11: Order Later
A12: WEN-BUR-014 | B12: 32 | C12: 3.4516129 | D12: 4 | E12: 9.271028 | F12: 0.2195122 | G12: 41 | H12: 54.806452 | I12: Critical | J12: Medium | K12: Priority
A13: WEN-BUR-015 | B13: 83 | C13: 5.8387097 | D13: 4 | E13: 14.21547 | G13: 66 | H13: 89.354839 | I13: Reorder | J13: Low | K13: Order Later
A14: WEN-BUR-017 | B14: 14 | C14: 0 | D14: 4 | E14: No Demand | F14: 0.6 | G14: 35 | H14: 35 | I14: Critical | J14: High | K14: High Priority
A15: WEN-BUR-018 | B15: 0 | C15: 1.7741935 | D15: 4 | E15: 0 | G15: 60 | H15: 67.096774 | I15: Stockout | J15: Very High | K15: Urgent
A16: WEN-BUR-019 | B16: 77 | C16: 3.6129032 | D16: 4 | E16: 21.3125 | G16: 73 | H16: 87.451613 | I16: Reorder | J16: Low | K16: Order Later
A17: WEN-BUR-021 | B17: 14 | C17: 5.8064516 | D17: 4 | E17: 2.4111111 | F17: 0.8028169 | G17: 71 | H17: 94.225806 | I17: Critical | J17: High | K17: High Priority
A18: WEN-BUR-022 | B18: 47 | C18: 1.6774194 | D18: 4 | E18: 28.019231 | G18: 45 | H18: 51.709677 | I18: Reorder | J18: Low | K18: Order Later
A19: WEN-BUR-023 | B19: 31 | C19: 1.7096774 | D19: 4 | E19: 18.132075 | F19: 0.41509434 | G19: 53 | H19: 59.83871 | I19: Critical | J19: High | K19: High Priority
A20: WEN-BUR-024 | B20: 53 | C20: 3.6451613 | D20: 4 | E20: 14.539823 | G20: 43 | H20: 57.580645 | I20: Reorder | J20: Low | K20: Order Later
A21: WEN-BUR-026 | B21: 10 | C21: 0 | D21: 4 | E21: No Demand | F21: 0.81481481 | G21: 54 | H21: 54 | I21: Critical | J21: High | K21: High Priority
A22: WEN-BUR-028 | B22: 0 | C22: 0 | D22: 4 | E22: No Demand | G22: 58 | H22: 58 | I22: Stockout | J22: Very High | K22: Urgent
A23: WEN-BUR-029 | B23: 51 | C23: 0 | D23: 4 | E23: No Demand | F23: 0.203125 | G23: 64 | H23: 64 | I23: Critical | J23: Medium | K23: Priority
A24: WEN-CHK-001 | B24: 32 | C24: 2 | D24: 4 | E24: 16 | G24: 30 | H24: 38 | I24: Reorder | J24: Low | K24: Order Later
A25: WEN-CHK-002 | B25: 25 | C25: 4.2580645 | D25: 4 | E25: 5.8712121 | F25: 0.6031746 | G25: 63 | H25: 80.032258 | I25: Critical | J25: High | K25: High Priority
A26: WEN-CHK-003 | B26: 64 | C26: 2.9677419 | D26: 4 | E26: 21.565217 | G26: 56 | H26: 67.870968 | I26: Reorder | J26: Low | K26: Order Later
A27: WEN-CHK-004 | B27: 36 | C27: 2.6129032 | D27: 4 | E27: 13.777778 | F27: 0.2 | G27: 45 | H27: 55.451613 | I27: Critical | J27: Medium | K27: Priority
A28: WEN-CHK-006 | B28: 40 | C28: 2.9032258 | D28: 4 | E28: 13.777778 | G28: 32 | H28: 43.612903 | I28: Reorder | J28: Low | K28: Order Later
A29: WEN-CHK-007 | B29: 22 | C29: 3.516129 | D29: 4 | E29: 6.2568807 | F29: 0.61403509 | G29: 57 | H29: 71.064516 | I29: Critical | J29: High | K29: High Priority
A30: WEN-CHK-008 | B30: 0 | C30: 0 | D30: 4 | E30: No Demand | G30: 37 | H30: 37 | I30: Stockout | J30: Very High | K30: Urgent
A31: WEN-CHK-009 | B31: 68 | C31: 2.1612903 | D31: 4 | E31: 31.462687 | G31: 62 | H31: 70.645161 | I31: Reorder | J31: Low | K31: Order Later
A32: WEN-CHK-011 | B32: 67 | C32: 5.9354839 | D32: 4 | E32: 11.288043 | G32: 55 | H32: 78.741935 | I32: Reorder | J32: Low | K32: Order Later
A33: WEN-CHK-012 | B33: 24 | C33: 5.1290323 | D33: 4 | E33: 4.6792453 | F33: 0.6 | G33: 60 | H33: 80.516129 | I33: Critical | J33: High | K33: High Priority
A34: WEN-CHK-013 | B34: 47 | C34: 8.7096774 | D34: 4 | E34: 5.3962963 | G34: 38 | H34: 72.83871 | I34: Reorder | J34: Medium | K34: Need Plan to Reorder
A35: WEN-CHK-014 | B35: 44 | C35: 0 | D35: 4 | E35: No Demand | F35: 0.2 | G35: 55 | H35: 55 | I35: Critical | J35: Medium | K35: Priority
A36: WEN-CHK-016 | B36: 34 | C36: 3.9677419 | D36: 4 | E36: 8.5691057 | G36: 30 | H36: 45.870968 | I36: Reorder | J36: Medium | K36: Need Plan to Reorder
A37: WEN-CHK-017 | B37: 15 | C37: 0 | D37: 4 | E37: No Demand | F37: 0.60526316 | G37: 38 | H37: 38 | I37: Critical | J37: High | K37: High Priority
A38: WEN-CHK-018 | B38: 0 | C38: 1.5806452 | D38: 4 | E38: 0 | G38: 34 | H38: 40.322581 | I38: Stockout | J38: Very High | K38: Urgent
A39: WEN-CHK-020 | B39: 51 | C39: 0 | D39: 4 | E39: No Demand | F39: 0.055555556 | G39: 54 | H39: 54 | I39: Critical | J39: Medium | K39: Priority
A40: WEN-CHK-021 | B40: 60 | C40: 2.1612903 | D40: 4 | E40: 27.761194 | G40: 54 | H40: 62.645161 | I40: Reorder | J40: Low | K40: Order Later
...

Sheet Order First
A1: SKU | B1: Suppliers | C1: Quantity Order Recommendation
A2: {=_xlfn._xlws.FILTER(_xlfn.ANCHORARRAY('Inventory Risk'!A2),(_xlfn.ANCHORARRAY('Inventory Risk'!K2)="High Priority")+(_xlfn.ANCHORARRAY('Inventory Risk'!K2)="Urgent"),"")} -> WEN-BUR-007 | B2: {=_xlfn.XLOOKUP(_xlfn.ANCHORARRAY(A2),Products[SKU],Products[Supplier])} -> Maple Prairie Foods | C2: {=_xlfn.XLOOKUP(_xlfn.ANCHORARRAY(A2),_xlfn.ANCHORARRAY('Inventory Risk'!A2),_xlfn.ANCHORARRAY('Inventory Risk'!H2))-_xlfn.XLOOKUP(_xlfn.ANCHORARRAY('Order First'!A2),_xlfn.ANCHORARRAY('Inventory Risk'!A2),_xlfn.ANCHORARRAY('Inventory Risk'!B2))} -> 29
A3: WEN-BUR-008 | B3: Maple Prairie Foods | C3: 90.451613
A4: WEN-BUR-012 | B4: Maple Prairie Foods | C4: 36.709677
A5: WEN-BUR-017 | B5: Maple Prairie Foods | C5: 21
A6: WEN-BUR-018 | B6: Maple Prairie Foods | C6: 67.096774
A7: WEN-BUR-021 | B7: Maple Prairie Foods | C7: 80.225806
A8: WEN-BUR-023 | B8: Maple Prairie Foods | C8: 28.83871
A9: WEN-BUR-026 | B9: Maple Prairie Foods | C9: 44
A10: WEN-BUR-028 | B10: Maple Prairie Foods | C10: 58
A11: WEN-CHK-002 | B11: Maple Prairie Foods | C11: 55.032258
A12: WEN-CHK-007 | B12: Maple Prairie Foods | C12: 49.064516
A13: WEN-CHK-008 | B13: Maple Prairie Foods | C13: 37
A14: WEN-CHK-012 | B14: Maple Prairie Foods | C14: 56.516129
... A61: WEN-COM-008 | B61: Canada QuickServe Distribution | C61: 55.645161

Sheet Need Plan to Order
A1: SKU | B1: Order Priority | C1: Stock on Hand Aug-31 | D1: Safety Stock | E1: Reorder Point
A2: {=_xlfn._xlws.FILTER(_xlfn.ANCHORARRAY('Inventory Risk'!A2),(_xlfn.ANCHORARRAY('Inventory Risk'!K2)<>"High Priority")*(_xlfn.ANCHORARRAY('Inventory Risk'!K2)<>"Urgent"),"")} -> WEN-BUR-001 | B2: {=_xlfn.XLOOKUP(_xlfn.ANCHORARRAY(A2),_xlfn.ANCHORARRAY('Inventory Risk'!A2),_xlfn.ANCHORARRAY('Inventory Risk'!K2))} -> Order Later | C2: {=_xlfn.XLOOKUP(_xlfn.ANCHORARRAY(A2),_xlfn.ANCHORARRAY('Inventory Risk'!A2),_xlfn.ANCHORARRAY('Inventory Risk'!B2))} -> 55 | D2: {=_xlfn.XLOOKUP(_xlfn.ANCHORARRAY(A2),_xlfn.ANCHORARRAY('Inventory Risk'!A2),_xlfn.ANCHORARRAY('Inventory Risk'!G2))} -> 52 | E2: {=_xlfn.XLOOKUP(_xlfn.ANCHORARRAY(A2),_xlfn.ANCHORARRAY('Inventory Risk'!A2),_xlfn.ANCHORARRAY('Inventory Risk'!H2))} -> 63.741935
A3: WEN-BUR-003 | B3: Order Later | C3: 73 | D3: 69 | E3: 74.806452
A4: WEN-BUR-004 | B4: Priority | C4: 59 | D4: 74 | E4: 85.612903
A5: WEN-BUR-005 | B5: Order Later | C5: 69 | D5: 65 | E5: 72.870968
A6: WEN-BUR-009 | B6: Need Plan to Reorder | C6: 50 | D6: 37 | E6: 55.967742
A7: WEN-BUR-011 | B7: Order Later | C7: 82 | D7: 75 | E7: 88.548387
A8: WEN-BUR-013 | B8: Order Later | C8: 52 | D8: 50 | E8: 55.935484
A9: WEN-BUR-014 | B9: Priority | C9: 32 | D9: 41 | E9: 54.806452
A10: WEN-BUR-015 | B10: Order Later | C10: 83 | D10: 66 | E10: 89.354839
A11: WEN-BUR-019 | B11: Order Later | C11: 77 | D11: 73 | E11: 87.451613
A12: WEN-BUR-022 | B12: Order Later | C12: 47 | D12: 45 | E12: 51.709677
A13: WEN-BUR-024 | B13: Order Later | C13: 53 | D13: 43 | E13: 57.580645
A14: WEN-BUR-029 | B14: Priority | C14: 51 | D14: 64 | E14: 64
... A92: WEN-COM-010 | B92: Priority | C92: 49 | D92: 52 | E92: 72.096774

Sheet Monthly Sales Trend 
A1: Row Labels | B1: Sum of Quantity Sold | C1: Sum of Sales Revenue (CAD)
A2: Jan | B2: 12937 | C2: 67927.27
A3: Feb | B3: 12211 | C3: 65107.06
A4: Mar | B4: 14191 | C4: 82412.34
A5: Apr | B5: 11754 | C5: 64271.79
A6: May | B6: 11464 | C6: 62401.24
A7: Jun | B7: 12645 | C7: 66895.85
A8: Jul | B8: 11605 | C8: 61779.05
A9: Aug | B9: 12720 | C9: 66809.47
A10: Grand Total | B10: 99527 | C10: 537604.07

Sheet Top 10 Selling Products
A1: Row Labels | B1: Sum of Quantity Sold
A2: Chocolate Cold Brew | B2: 1138
A3: Hot Coffee - Small | B3: 1113
A4: Milk - Chocolate | B4: 999
A5: Caramel Cold Brew | B5: 994
A6: Spicy Southwest Double Burger | B6: 979
A7: Hot Coffee - Medium | B7: 955
A8: Apple Juice | B8: 943
A9: Strawberry Lemonade - Medium | B9: 941
A10: Lemonade - Large | B10: 881
A11: Diet Cola - Small | B11: 877
A12: Grand Total | B12: 9820

Sheet Store Analysis
A3: Row Labels | B3: Sum of Sales Revenue (CAD)
A4: Kamloops - Downtown | B4: 226938.64
A5: Drive-Thru | B5: 108778.63
A6: Takeout | B6: 49033.16
A7: Dine-In | B7: 41706.45
A8: Delivery | B8: 27420.4
A9: Kamloops - Aberdeen | B9: 177723.75
A10: Drive-Thru | B10: 82478
A11: Takeout | B11: 41131.36
A12: Dine-In | B12: 32990.25
A13: Delivery | B13: 21124.14
A14: Kamloops - Valleyview | B14: 132941.68
A15: Drive-Thru | B15: 61218.85
... A19: Grand Total | B19: 537604.07
